package kotlinx.coroutines.io;

import java.util.concurrent.CancellationException;
import kotlin.Metadata;
import kotlin.Unit;
import kotlin.jvm.functions.Function1;
import kotlin.jvm.internal.Lambda;
import org.jetbrains.annotations.Nullable;
/* compiled from: ByteBufferChannel.kt */
@Metadata(bv = {1, 0, 3}, d1 = {"\u0000\u000e\n\u0000\n\u0002\u0010\u0002\n\u0000\n\u0002\u0010\u0003\n\u0000\u0010\u0000\u001a\u00020\u00012\b\u0010\u0002\u001a\u0004\u0018\u00010\u0003H\nÂ¢\u0006\u0002\b\u0004"}, d2 = {"<anonymous>", "", "cause", "", "invoke"}, k = 3, mv = {1, 1, 13})
/* loaded from: classes4.dex */
final class ByteBufferChannel$attachJob$1 extends Lambda implements Function1<Throwable, Unit> {
    final /* synthetic */ ByteBufferChannel this$0;

    /* JADX INFO: Access modifiers changed from: package-private */
    /* JADX WARN: 'super' call moved to the top of the method (can break code semantics) */
    public ByteBufferChannel$attachJob$1(ByteBufferChannel byteBufferChannel) {
        super(1);
        this.this$0 = byteBufferChannel;
    }

    @Override // kotlin.jvm.functions.Function1
    /* renamed from: invoke */
    public /* bridge */ /* synthetic */ Unit mo12165invoke(Throwable th) {
        invoke2(th);
        return Unit.INSTANCE;
    }

    /* renamed from: invoke  reason: avoid collision after fix types in other method */
    public final void invoke2(@Nullable Throwable th) {
        this.this$0.attachedJob = null;
        if (th != null) {
            ByteBufferChannel byteBufferChannel = this.this$0;
            CancellationException cancellationException = new CancellationException("Channel closed due to job failure");
            cancellationException.initCause(th);
            byteBufferChannel.cancel(cancellationException);
        }
    }
}
